<sdf version='1.6'>
  <world name='default'>
    <light name='sun' type='directional'>
      <cast_shadows>1</cast_shadows>
      <pose frame=''>0 0 10 0 -0 0</pose>
      <diffuse>0.8 0.8 0.8 1</diffuse>
      <specular>0.2 0.2 0.2 1</specular>
      <attenuation>
        <range>1000</range>
        <constant>0.9</constant>
        <linear>0.01</linear>
        <quadratic>0.001</quadratic>
      </attenuation>
      <direction>-0.5 0.1 -0.9</direction>
    </light>
    <model name='ground_plane'>
      <static>1</static>
      <link name='link'>
        <collision name='collision'>
          <geometry>
            <plane>
              <normal>0 0 1</normal>
              <size>100 100</size>
            </plane>
          </geometry>
          <surface>
            <contact>
              <collide_bitmask>65535</collide_bitmask>
              <ode/>
            </contact>
            <friction>
              <ode>
                <mu>100</mu>
                <mu2>50</mu2>
              </ode>
              <torsional>
                <ode/>
              </torsional>
            </friction>
            <bounce/>
          </surface>
          <max_contacts>10</max_contacts>
        </collision>
        <visual name='visual'>
          <cast_shadows>0</cast_shadows>
          <geometry>
            <plane>
              <normal>0 0 1</normal>
              <size>100 100</size>
            </plane>
          </geometry>
          <material>
            <script>
              <uri>file://media/materials/scripts/gazebo.material</uri>
              <name>Gazebo/Grey</name>
            </script>
          </material>
        </visual>
        <self_collide>0</self_collide>
        <kinematic>0</kinematic>
      </link>
    </model>
    <gravity>0 0 -9.8</gravity>
    <magnetic_field>6e-06 2.3e-05 -4.2e-05</magnetic_field>
    <atmosphere type='adiabatic'/>
    <physics name='default_physics' default='0' type='ode'>
      <max_step_size>0.001</max_step_size>
      <real_time_factor>1</real_time_factor>
      <real_time_update_rate>1000</real_time_update_rate>
    </physics>
    <scene>
      <ambient>0.4 0.4 0.4 1</ambient>
      <background>0.7 0.7 0.7 1</background>
      <shadows>1</shadows>
    </scene>
    <spherical_coordinates>
      <surface_model>EARTH_WGS84</surface_model>
      <latitude_deg>0</latitude_deg>
      <longitude_deg>0</longitude_deg>
      <elevation>0</elevation>
      <heading_deg>0</heading_deg>
    </spherical_coordinates>
    <model name='Untitled'>
      <pose frame=''>1.15444 0.530645 0 0 -0 0</pose>
      <link name='Wall_3'>
        <collision name='Wall_3_Collision'>
          <geometry>
            <box>
              <size>12.5 0.15 2.5</size>
            </box>
          </geometry>
          <pose frame=''>0 0 1.25 0 -0 0</pose>
          <max_contacts>10</max_contacts>
          <surface>
            <contact>
              <ode/>
            </contact>
            <bounce/>
            <friction>
              <torsional>
                <ode/>
              </torsional>
              <ode/>
            </friction>
          </surface>
        </collision>
        <visual name='Wall_3_Visual'>
          <pose frame=''>0 0 1.25 0 -0 0</pose>
          <geometry>
            <box>
              <size>12.5 0.15 2.5</size>
            </box>
          </geometry>
          <material>
            <script>
              <uri>file://media/materials/scripts/gazebo.material</uri>
              <name>Gazebo/Grey</name>
            </script>
            <ambient>0.921569 0.807843 0.615686 1</ambient>
          </material>
          <meta>
            <layer>0</layer>
          </meta>
        </visual>
        <pose frame=''>-5.3 0 0 0 0 -1.5708</pose>
        <self_collide>0</self_collide>
        <kinematic>0</kinematic>
      </link>
      <link name='Wall_4'>
        <collision name='Wall_4_Collision'>
          <geometry>
            <box>
              <size>10.75 0.15 2.5</size>
            </box>
          </geometry>
          <pose frame=''>0 0 1.25 0 -0 0</pose>
          <max_contacts>10</max_contacts>
          <surface>
            <contact>
              <ode/>
            </contact>
            <bounce/>
            <friction>
              <torsional>
                <ode/>
              </torsional>
              <ode/>
            </friction>
          </surface>
        </collision>
        <visual name='Wall_4_Visual'>
          <pose frame=''>0 0 1.25 0 -0 0</pose>
          <geometry>
            <box>
              <size>10.75 0.15 2.5</size>
            </box>
          </geometry>
          <material>
            <script>
              <uri>file://media/materials/scripts/gazebo.material</uri>
              <name>Gazebo/Grey</name>
            </script>
            <ambient>1 0.764706 0.305882 1</ambient>
          </material>
          <meta>
            <layer>0</layer>
          </meta>
        </visual>
        <pose frame=''>0 -6.175 0 0 -0 0</pose>
        <self_collide>0</self_collide>
        <kinematic>0</kinematic>
      </link>
      <link name='Wall_5'>
        <collision name='Wall_5_Collision'>
          <geometry>
            <box>
              <size>12.5 0.15 2.5</size>
            </box>
          </geometry>
          <pose frame=''>0 0 1.25 0 -0 0</pose>
          <max_contacts>10</max_contacts>
          <surface>
            <contact>
              <ode/>
            </contact>
            <bounce/>
            <friction>
              <torsional>
                <ode/>
              </torsional>
              <ode/>
            </friction>
          </surface>
        </collision>
        <visual name='Wall_5_Visual'>
          <pose frame=''>0 0 1.25 0 -0 0</pose>
          <geometry>
            <box>
              <size>12.5 0.15 2.5</size>
            </box>
          </geometry>
          <material>
            <script>
              <uri>file://media/materials/scripts/gazebo.material</uri>
              <name>Gazebo/Grey</name>
            </script>
            <ambient>1 0.764706 0.305882 1</ambient>
          </material>
          <meta>
            <layer>0</layer>
          </meta>
        </visual>
        <pose frame=''>5.3 0 0 0 -0 1.5708</pose>
        <self_collide>0</self_collide>
        <kinematic>0</kinematic>
      </link>
      <link name='Wall_6'>
        <collision name='Wall_6_Collision'>
          <geometry>
            <box>
              <size>10.75 0.15 2.5</size>
            </box>
          </geometry>
          <pose frame=''>0 0 1.25 0 -0 0</pose>
          <max_contacts>10</max_contacts>
          <surface>
            <contact>
              <ode/>
            </contact>
            <bounce/>
            <friction>
              <torsional>
                <ode/>
              </torsional>
              <ode/>
            </friction>
          </surface>
        </collision>
        <visual name='Wall_6_Visual'>
          <pose frame=''>0 0 1.25 0 -0 0</pose>
          <geometry>
            <box>
              <size>10.75 0.15 2.5</size>
            </box>
          </geometry>
          <material>
            <script>
              <uri>file://media/materials/scripts/gazebo.material</uri>
              <name>Gazebo/Grey</name>
            </script>
            <ambient>0.996078 0.47451 0.0196078 1</ambient>
          </material>
          <meta>
            <layer>0</layer>
          </meta>
        </visual>
        <pose frame=''>0 6.175 0 0 -0 3.14159</pose>
        <self_collide>0</self_collide>
        <kinematic>0</kinematic>
      </link>
      <static>1</static>
    </model>
    <model name='Untitled_0'>
      <model name='Dumpster'>
        <link name='link'>
          <collision name='collision'>
            <geometry>
              <mesh>
                <scale>1.5 1.5 1.5</scale>
                <uri>model://dumpster/meshes/dumpster.dae</uri>
              </mesh>
            </geometry>
            <max_contacts>10</max_contacts>
            <surface>
              <contact>
                <ode/>
              </contact>
              <bounce/>
              <friction>
                <torsional>
                  <ode/>
                </torsional>
                <ode/>
              </friction>
            </surface>
          </collision>
          <visual name='visual'>
            <geometry>
              <mesh>
                <scale>1.5 1.5 1.5</scale>
                <uri>model://dumpster/meshes/dumpster.dae</uri>
              </mesh>
            </geometry>
            <material>
              <script>
                <uri>model://dumpster/materials/scripts</uri>
                <uri>model://dumpster/materials/textures</uri>
                <name>Dumpster/Diffuse</name>
              </script>
            </material>
          </visual>
          <self_collide>0</self_collide>
          <inertial>
            <inertia>
              <ixx>1</ixx>
              <ixy>0</ixy>
              <ixz>0</ixz>
              <iyy>1</iyy>
              <iyz>0</iyz>
              <izz>1</izz>
            </inertia>
            <mass>1</mass>
          </inertial>
          <kinematic>0</kinematic>
        </link>
        <pose frame=''>-3.07789 -5.74603 -0.22703 0 -0 0</pose>
      </model>
      <model name='bowl'>
        <link name='link'>
          <inertial>
            <pose frame=''>0 0 0.0175 0 -0 0</pose>
            <mass>0.1</mass>
            <inertia>
              <ixx>0.000250308</ixx>
              <ixy>0</ixy>
              <ixz>0</ixz>
              <iyy>0.000250308</iyy>
              <iyz>0</iyz>
              <izz>0.0004802</izz>
            </inertia>
          </inertial>
          <collision name='collision'>
            <pose frame=''>0 0 0.0175 0 -0 0</pose>
            <geometry>
              <cylinder>
                <radius>0.098</radius>
                <length>0.035</length>
              </cylinder>
            </geometry>
            <max_contacts>10</max_contacts>
            <surface>
              <contact>
                <ode/>
              </contact>
              <bounce/>
              <friction>
                <torsional>
                  <ode/>
                </torsional>
                <ode/>
              </friction>
            </surface>
          </collision>
          <visual name='visual'>
            <geometry>
              <mesh>
                <uri>model://bowl/meshes/bowl.dae</uri>
              </mesh>
            </geometry>
          </visual>
          <self_collide>0</self_collide>
          <kinematic>0</kinematic>
        </link>
        <pose frame=''>-1.72613 3.15098 0.95515 0 -0 0</pose>
      </model>
      <model name='cardboard_box'>
        <pose frame=''>-0.899941 3.16309 -0.07703 0 -0 0</pose>
        <link name='link'>
          <inertial>
            <mass>2</mass>
            <inertia>
              <ixx>0.0416667</ixx>
              <ixy>0</ixy>
              <ixz>0</ixz>
              <iyy>0.0566667</iyy>
              <iyz>0</iyz>
              <izz>0.0683333</izz>
            </inertia>
          </inertial>
          <collision name='collision'>
            <geometry>
              <box>
                <size>0.5 0.4 0.3</size>
              </box>
            </geometry>
            <surface>
              <friction>
                <ode>
                  <mu>1</mu>
                  <mu2>1</mu2>
                </ode>
                <torsional>
                  <ode/>
                </torsional>
              </friction>
              <contact>
                <ode>
                  <kp>1e+07</kp>
                  <kd>1</kd>
                  <min_depth>0.001</min_depth>
                  <max_vel>0.1</max_vel>
                </ode>
              </contact>
              <bounce/>
            </surface>
            <max_contacts>10</max_contacts>
          </collision>
          <visual name='visual'>
            <pose frame=''>0 0 -0.15 0 -0 0</pose>
            <geometry>
              <mesh>
                <uri>model://cardboard_box/meshes/cardboard_box.dae</uri>
                <scale>1.25932 1.00745 0.755591</scale>
              </mesh>
            </geometry>
          </visual>
          <self_collide>0</self_collide>
          <kinematic>0</kinematic>
        </link>
      </model>
      <model name='prius_hybrid'>
        <pose frame=''>3.45087 2.19664 -0.19703 0 -0 0</pose>
        <link name='chassis'>
          <inertial>
            <mass>1326</mass>
            <pose frame=''>0 -0.266 0.48 0 -0 0</pose>
            <inertia>
              <ixx>2581.13</ixx>
              <ixy>0</ixy>
              <iyy>591.308</iyy>
              <ixz>0</ixz>
              <iyz>0</iyz>
              <izz>2681.95</izz>
            </inertia>
          </inertial>
          <visual name='chassis_visual'>
            <geometry>
              <mesh>
                <uri>model://prius_hybrid/meshes/Hybrid.obj</uri>
                <scale>0.01 0.01 0.01</scale>
                <submesh>
                  <name>Hybrid</name>
                  <center>0</center>
                </submesh>
              </mesh>
            </geometry>
          </visual>
          <visual name='interior_visual'>
            <geometry>
              <mesh>
                <uri>model://prius_hybrid/meshes/Hybrid.obj</uri>
                <scale>0.01 0.01 0.01</scale>
                <submesh>
                  <name>Hybrid_Interior</name>
                  <center>0</center>
                </submesh>
              </mesh>
            </geometry>
          </visual>
          <visual name='windows_visual'>
            <geometry>
              <mesh>
                <uri>model://prius_hybrid/meshes/Hybrid.obj</uri>
                <scale>0.01 0.01 0.01</scale>
                <submesh>
                  <name>Hybrid_Windows</name>
                  <center>0</center>
                </submesh>
              </mesh>
            </geometry>
          </visual>
          <collision name='chassis'>
            <pose frame=''>0 0.05 0.625 0 -0 0</pose>
            <geometry>
              <box>
                <size>1.7526 2.1 0.95</size>
              </box>
            </geometry>
            <max_contacts>10</max_contacts>
            <surface>
              <contact>
                <ode/>
              </contact>
              <bounce/>
              <friction>
                <torsional>
                  <ode/>
                </torsional>
                <ode/>
              </friction>
            </surface>
          </collision>
          <collision name='front_bumper'>
            <pose frame=''>0 -2 0.458488 0 -0 0</pose>
            <geometry>
              <box>
                <size>1.33728 0.48 0.566691</size>
              </box>
            </geometry>
            <max_contacts>10</max_contacts>
            <surface>
              <contact>
                <ode/>
              </contact>
              <bounce/>
              <friction>
                <torsional>
                  <ode/>
                </torsional>
                <ode/>
              </friction>
            </surface>
          </collision>
          <collision name='hood'>
            <pose frame=''>0 -1.90084 0.676305 0.341247 -0 0</pose>
            <geometry>
              <box>
                <size>1.59797 0.493107 0.265468</size>
              </box>
            </geometry>
            <max_contacts>10</max_contacts>
            <surface>
              <contact>
                <ode/>
              </contact>
              <bounce/>
              <friction>
                <torsional>
                  <ode/>
                </torsional>
                <ode/>
              </friction>
            </surface>
          </collision>
          <collision name='windshield'>
            <pose frame=''>0 -0.875105 1.03227 0.335476 -0 0</pose>
            <geometry>
              <box>
                <size>1.16838 1.65425 0.272347</size>
              </box>
            </geometry>
            <max_contacts>10</max_contacts>
            <surface>
              <contact>
                <ode/>
              </contact>
              <bounce/>
              <friction>
                <torsional>
                  <ode/>
                </torsional>
                <ode/>
              </friction>
            </surface>
          </collision>
          <collision name='top_front'>
            <pose frame=''>0 0.161236 1.38604 0.13503 -0 0</pose>
            <geometry>
              <box>
                <size>1.27915 0.625988 0.171868</size>
              </box>
            </geometry>
            <max_contacts>10</max_contacts>
            <surface>
              <contact>
                <ode/>
              </contact>
              <bounce/>
              <friction>
                <torsional>
                  <ode/>
                </torsional>
                <ode/>
              </friction>
            </surface>
          </collision>
          <collision name='top_rear'>
            <pose frame=''>0 0.817696 1.36007 -0.068997 0 0</pose>
            <geometry>
              <box>
                <size>1.28513 0.771189 0.226557</size>
              </box>
            </geometry>
            <max_contacts>10</max_contacts>
            <surface>
              <contact>
                <ode/>
              </contact>
              <bounce/>
              <friction>
                <torsional>
                  <ode/>
                </torsional>
                <ode/>
              </friction>
            </surface>
          </collision>
          <collision name='rear_window'>
            <pose frame=''>0 1.64053 1.17513 -0.262017 0 0</pose>
            <geometry>
              <box>
                <size>1.26785 1.11634 0.244286</size>
              </box>
            </geometry>
            <max_contacts>10</max_contacts>
            <surface>
              <contact>
                <ode/>
              </contact>
              <bounce/>
              <friction>
                <torsional>
                  <ode/>
                </torsional>
                <ode/>
              </friction>
            </surface>
          </collision>
          <collision name='trunk'>
            <pose frame=''>0 1.63706 0.88818 0 -0 0</pose>
            <geometry>
              <box>
                <size>1.78806 1.13899 0.482746</size>
              </box>
            </geometry>
            <max_contacts>10</max_contacts>
            <surface>
              <contact>
                <ode/>
              </contact>
              <bounce/>
              <friction>
                <torsional>
                  <ode/>
                </torsional>
                <ode/>
              </friction>
            </surface>
          </collision>
          <collision name='back_bumper'>
            <pose frame=''>0 2.05445 0.57787 0 -0 0</pose>
            <geometry>
              <box>
                <size>1.78165 0.512093 0.581427</size>
              </box>
            </geometry>
            <max_contacts>10</max_contacts>
            <surface>
              <contact>
                <ode/>
              </contact>
              <bounce/>
              <friction>
                <torsional>
                  <ode/>
                </torsional>
                <ode/>
              </friction>
            </surface>
          </collision>
          <self_collide>0</self_collide>
          <kinematic>0</kinematic>
        </link>
        <link name='steering_wheel'>
          <pose frame=''>0.357734 -0.627868 0.988243 -1.3021 0 0</pose>
          <inertial>
            <mass>1</mass>
            <inertia>
              <ixx>0.145833</ixx>
              <ixy>0</ixy>
              <ixz>0</ixz>
              <iyy>0.145833</iyy>
              <iyz>0</iyz>
              <izz>0.125</izz>
            </inertia>
          </inertial>
          <collision name='collision'>
            <geometry>
              <cylinder>
                <radius>0.178172</radius>
                <length>0.041845</length>
              </cylinder>
            </geometry>
            <surface>
              <contact>
                <ode>
                  <min_depth>0.003</min_depth>
                </ode>
              </contact>
              <bounce/>
              <friction>
                <torsional>
                  <ode/>
                </torsional>
                <ode/>
              </friction>
            </surface>
            <max_contacts>10</max_contacts>
          </collision>
          <visual name='visual'>
            <pose frame=''>0 0 0 1.3021 -0 0</pose>
            <geometry>
              <mesh>
                <uri>model://prius_hybrid/meshes/Hybrid.obj</uri>
                <scale>0.01 0.01 0.01</scale>
                <submesh>
                  <name>Steering_Wheel</name>
                  <center>1</center>
                </submesh>
              </mesh>
            </geometry>
          </visual>
          <self_collide>0</self_collide>
          <kinematic>0</kinematic>
        </link>
        <link name='front_left_wheel'>
          <pose frame=''>0.76 -1.41 0.3 0 -0 0</pose>
          <inertial>
            <mass>11</mass>
            <inertia>
              <ixx>0.586312</ixx>
              <ixy>0</ixy>
              <iyy>0.335529</iyy>
              <ixz>0</ixz>
              <iyz>0</iyz>
              <izz>0.335529</izz>
            </inertia>
          </inertial>
          <visual name='visual'>
            <pose frame=''>0.04 0 0 0 -0 0</pose>
            <geometry>
              <mesh>
                <uri>model://prius_hybrid/meshes/Hybrid.obj</uri>
                <scale>0.01 0.01 0.01</scale>
                <submesh>
                  <name>Wheel_Front_Left_</name>
                  <center>1</center>
                </submesh>
              </mesh>
            </geometry>
          </visual>
          <collision name='collision'>
            <pose frame=''>0 0 0 3.14159 1.57079 3.14159</pose>
            <geometry>
              <sphere>
                <radius>0.31265</radius>
              </sphere>
            </geometry>
            <surface>
              <friction>
                <ode>
                  <mu>0.9</mu>
                  <mu2>0.9</mu2>
                  <slip1>0</slip1>
                  <slip2>0</slip2>
                </ode>
                <torsional>
                  <ode/>
                </torsional>
              </friction>
              <contact>
                <ode>
                  <min_depth>0.001</min_depth>
                  <kp>1e+09</kp>
                </ode>
              </contact>
              <bounce/>
            </surface>
            <max_contacts>10</max_contacts>
          </collision>
          <self_collide>0</self_collide>
          <kinematic>0</kinematic>
        </link>
        <link name='front_right_wheel'>
          <pose frame=''>-0.76 -1.41 0.3 0 -0 0</pose>
          <inertial>
            <mass>11</mass>
            <inertia>
              <ixx>0.586312</ixx>
              <ixy>0</ixy>
              <iyy>0.335529</iyy>
              <ixz>0</ixz>
              <iyz>0</iyz>
              <izz>0.335529</izz>
            </inertia>
          </inertial>
          <visual name='visual'>
            <pose frame=''>-0.04 0 0 0 -0 0</pose>
            <pose frame=''>0 0 0 0 -0 0</pose>
            <geometry>
              <mesh>
                <uri>model://prius_hybrid/meshes/Hybrid.obj</uri>
                <scale>0.01 0.01 0.01</scale>
                <submesh>
                  <name>Wheel_Front_Right</name>
                  <center>1</center>
                </submesh>
              </mesh>
            </geometry>
          </visual>
          <collision name='collision'>
            <pose frame=''>0 0 0 3.14159 1.57079 3.14159</pose>
            <geometry>
              <sphere>
                <radius>0.31265</radius>
              </sphere>
            </geometry>
            <surface>
              <friction>
                <ode>
                  <mu>0.9</mu>
                  <mu2>0.9</mu2>
                  <slip1>0</slip1>
                  <slip2>0</slip2>
                </ode>
                <torsional>
                  <ode/>
                </torsional>
              </friction>
              <contact>
                <ode>
                  <min_depth>0.001</min_depth>
                  <kp>1e+09</kp>
                </ode>
              </contact>
              <bounce/>
            </surface>
            <max_contacts>10</max_contacts>
          </collision>
          <self_collide>0</self_collide>
          <kinematic>0</kinematic>
        </link>
        <link name='rear_left_wheel'>
          <pose frame=''>0.786 1.45 0.3 0 -0 0</pose>
          <inertial>
            <mass>11</mass>
            <inertia>
              <ixx>0.586312</ixx>
              <ixy>0</ixy>
              <iyy>0.335529</iyy>
              <ixz>0</ixz>
              <iyz>0</iyz>
              <izz>0.335529</izz>
            </inertia>
          </inertial>
          <visual name='visual'>
            <pose frame=''>0.04 0 0 0 -0 0</pose>
            <geometry>
              <mesh>
                <uri>model://prius_hybrid/meshes/Hybrid.obj</uri>
                <scale>0.01 0.01 0.01</scale>
                <submesh>
                  <name>Wheel_Front_Left_</name>
                  <center>1</center>
                </submesh>
              </mesh>
            </geometry>
          </visual>
          <collision name='collision'>
            <pose frame=''>0 0 0 3.14159 1.57079 3.14159</pose>
            <geometry>
              <sphere>
                <radius>0.31265</radius>
              </sphere>
            </geometry>
            <surface>
              <friction>
                <ode>
                  <mu>1.1</mu>
                  <mu2>1.1</mu2>
                  <slip1>0</slip1>
                  <slip2>0</slip2>
                </ode>
                <torsional>
                  <ode/>
                </torsional>
              </friction>
              <contact>
                <ode>
                  <min_depth>0.001</min_depth>
                  <kp>1e+09</kp>
                </ode>
              </contact>
              <bounce/>
            </surface>
            <max_contacts>10</max_contacts>
          </collision>
          <self_collide>0</self_collide>
          <kinematic>0</kinematic>
        </link>
        <link name='rear_right_wheel'>
          <pose frame=''>-0.786 1.45 0.3 0 -0 0</pose>
          <inertial>
            <mass>11</mass>
            <inertia>
              <ixx>0.586312</ixx>
              <ixy>0</ixy>
              <iyy>0.335529</iyy>
              <ixz>0</ixz>
              <iyz>0</iyz>
              <izz>0.335529</izz>
            </inertia>
          </inertial>
          <visual name='visual'>
            <pose frame=''>-0.04 0 0 0 -0 0</pose>
            <geometry>
              <mesh>
                <uri>model://prius_hybrid/meshes/Hybrid.obj</uri>
                <scale>0.01 0.01 0.01</scale>
                <submesh>
                  <name>Wheel_Front_Right</name>
                  <center>1</center>
                </submesh>
              </mesh>
            </geometry>
          </visual>
          <collision name='collision'>
            <pose frame=''>0 0 0 3.14159 1.57079 3.14159</pose>
            <geometry>
              <sphere>
                <radius>0.31265</radius>
              </sphere>
            </geometry>
            <surface>
              <friction>
                <ode>
                  <mu>1.1</mu>
                  <mu2>1.1</mu2>
                  <slip1>0</slip1>
                  <slip2>0</slip2>
                </ode>
                <torsional>
                  <ode/>
                </torsional>
              </friction>
              <contact>
                <ode>
                  <min_depth>0.001</min_depth>
                  <kp>1e+09</kp>
                </ode>
              </contact>
              <bounce/>
            </surface>
            <max_contacts>10</max_contacts>
          </collision>
          <self_collide>0</self_collide>
          <kinematic>0</kinematic>
        </link>
        <joint name='front_left_combined_joint' type='universal'>
          <pose frame=''>0 0 0 -0.087266 0 0</pose>
          <child>front_left_wheel</child>
          <parent>chassis</parent>
          <axis>
            <xyz>0 0 1</xyz>
            <limit>
              <lower>-0.8727</lower>
              <upper>0.8727</upper>
            </limit>
            <use_parent_model_frame>0</use_parent_model_frame>
            <dynamics>
              <spring_reference>0</spring_reference>
              <spring_stiffness>0</spring_stiffness>
            </dynamics>
          </axis>
          <axis2>
            <xyz>1 0 0</xyz>
            <dynamics>
              <friction>18.0474</friction>
              <spring_reference>0</spring_reference>
              <spring_stiffness>0</spring_stiffness>
            </dynamics>
            <use_parent_model_frame>0</use_parent_model_frame>
          </axis2>
        </joint>
        <joint name='front_right_combined_joint' type='universal'>
          <pose frame=''>0 0 0 -0.087266 0 0</pose>
          <child>front_right_wheel</child>
          <parent>chassis</parent>
          <axis>
            <xyz>0 0 1</xyz>
            <limit>
              <lower>-0.8727</lower>
              <upper>0.8727</upper>
            </limit>
            <use_parent_model_frame>0</use_parent_model_frame>
            <dynamics>
              <spring_reference>0</spring_reference>
              <spring_stiffness>0</spring_stiffness>
            </dynamics>
          </axis>
          <axis2>
            <xyz>1 0 0</xyz>
            <dynamics>
              <friction>18.0474</friction>
              <spring_reference>0</spring_reference>
              <spring_stiffness>0</spring_stiffness>
            </dynamics>
            <use_parent_model_frame>0</use_parent_model_frame>
          </axis2>
        </joint>
        <link name='rear_axle'>
          <pose frame=''>0 1.45 0.3 0 -0 0</pose>
          <inertial>
            <mass>30</mass>
            <inertia>
              <ixx>0.084375</ixx>
              <ixy>0</ixy>
              <iyy>4.64581</iyy>
              <ixz>0</ixz>
              <iyz>0</iyz>
              <izz>4.64581</izz>
            </inertia>
          </inertial>
          <visual name='visual'>
            <pose frame=''>0 0 0 3.14159 1.57079 3.14159</pose>
            <geometry>
              <cylinder>
                <length>1.357</length>
                <radius>0.075</radius>
              </cylinder>
            </geometry>
            <material>
              <script>
                <name>Gazebo/Grey</name>
                <uri>file://media/materials/scripts/gazebo.material</uri>
              </script>
            </material>
          </visual>
          <self_collide>0</self_collide>
          <kinematic>0</kinematic>
        </link>
        <joint name='rear_axle_joint' type='revolute'>
          <child>rear_axle</child>
          <parent>chassis</parent>
          <axis>
            <xyz>0 1 0</xyz>
            <limit>
              <lower>-0.0508906</lower>
              <upper>0.0508906</upper>
            </limit>
            <dynamics>
              <spring_stiffness>20000</spring_stiffness>
              <damping>2000</damping>
              <spring_reference>0</spring_reference>
            </dynamics>
            <use_parent_model_frame>0</use_parent_model_frame>
          </axis>
        </joint>
        <joint name='rear_left_wheel_joint' type='revolute'>
          <child>rear_left_wheel</child>
          <parent>rear_axle</parent>
          <axis>
            <xyz>1 0 0</xyz>
            <dynamics>
              <friction>12.0316</friction>
              <spring_reference>0</spring_reference>
              <spring_stiffness>0</spring_stiffness>
            </dynamics>
            <use_parent_model_frame>0</use_parent_model_frame>
            <limit>
              <lower>-1e+16</lower>
              <upper>1e+16</upper>
            </limit>
          </axis>
        </joint>
        <joint name='rear_right_wheel_joint' type='revolute'>
          <child>rear_right_wheel</child>
          <parent>rear_axle</parent>
          <axis>
            <xyz>1 0 0</xyz>
            <dynamics>
              <friction>12.0316</friction>
              <spring_reference>0</spring_reference>
              <spring_stiffness>0</spring_stiffness>
            </dynamics>
            <use_parent_model_frame>0</use_parent_model_frame>
            <limit>
              <lower>-1e+16</lower>
              <upper>1e+16</upper>
            </limit>
          </axis>
        </joint>
        <joint name='steering_joint' type='revolute'>
          <pose frame=''>-0.002 0 0 0 -0 0</pose>
          <parent>chassis</parent>
          <child>steering_wheel</child>
          <axis>
            <xyz>0 0.964095 0.265556</xyz>
            <limit>
              <lower>-7.85</lower>
              <upper>7.85</upper>
            </limit>
            <dynamics>
              <damping>1</damping>
              <spring_reference>0</spring_reference>
              <spring_stiffness>0</spring_stiffness>
            </dynamics>
            <use_parent_model_frame>1</use_parent_model_frame>
          </axis>
          <physics>
            <ode>
              <cfm_damping>1</cfm_damping>
              <limit>
                <cfm>0</cfm>
                <erp>0.2</erp>
              </limit>
            </ode>
          </physics>
        </joint>
      </model>
      <model name='table'>
        <static>1</static>
        <link name='link'>
          <collision name='surface'>
            <pose frame=''>0 0 1 0 -0 0</pose>
            <geometry>
              <box>
                <size>1.5 0.8 0.03</size>
              </box>
            </geometry>
            <surface>
              <friction>
                <ode>
                  <mu>0.6</mu>
                  <mu2>0.6</mu2>
                </ode>
                <torsional>
                  <ode/>
                </torsional>
              </friction>
              <contact>
                <ode/>
              </contact>
              <bounce/>
            </surface>
            <max_contacts>10</max_contacts>
          </collision>
          <visual name='visual1'>
            <pose frame=''>0 0 1 0 -0 0</pose>
            <geometry>
              <box>
                <size>1.5 0.8 0.03</size>
              </box>
            </geometry>
            <material>
              <script>
                <uri>file://media/materials/scripts/gazebo.material</uri>
                <name>Gazebo/Wood</name>
              </script>
            </material>
          </visual>
          <collision name='front_left_leg'>
            <pose frame=''>0.68 0.38 0.5 0 -0 0</pose>
            <geometry>
              <cylinder>
                <radius>0.02</radius>
                <length>1</length>
              </cylinder>
            </geometry>
            <max_contacts>10</max_contacts>
            <surface>
              <contact>
                <ode/>
              </contact>
              <bounce/>
              <friction>
                <torsional>
                  <ode/>
                </torsional>
                <ode/>
              </friction>
            </surface>
          </collision>
          <visual name='front_left_leg'>
            <pose frame=''>0.68 0.38 0.5 0 -0 0</pose>
            <geometry>
              <cylinder>
                <radius>0.02</radius>
                <length>1</length>
              </cylinder>
            </geometry>
            <material>
              <script>
                <uri>file://media/materials/scripts/gazebo.material</uri>
                <name>Gazebo/Grey</name>
              </script>
            </material>
          </visual>
          <collision name='front_right_leg'>
            <pose frame=''>0.68 -0.38 0.5 0 -0 0</pose>
            <geometry>
              <cylinder>
                <radius>0.02</radius>
                <length>1</length>
              </cylinder>
            </geometry>
            <max_contacts>10</max_contacts>
            <surface>
              <contact>
                <ode/>
              </contact>
              <bounce/>
              <friction>
                <torsional>
                  <ode/>
                </torsional>
                <ode/>
              </friction>
            </surface>
          </collision>
          <visual name='front_right_leg'>
            <pose frame=''>0.68 -0.38 0.5 0 -0 0</pose>
            <geometry>
              <cylinder>
                <radius>0.02</radius>
                <length>1</length>
              </cylinder>
            </geometry>
            <material>
              <script>
                <uri>file://media/materials/scripts/gazebo.material</uri>
                <name>Gazebo/Grey</name>
              </script>
            </material>
          </visual>
          <collision name='back_right_leg'>
            <pose frame=''>-0.68 -0.38 0.5 0 -0 0</pose>
            <geometry>
              <cylinder>
                <radius>0.02</radius>
                <length>1</length>
              </cylinder>
            </geometry>
            <max_contacts>10</max_contacts>
            <surface>
              <contact>
                <ode/>
              </contact>
              <bounce/>
              <friction>
                <torsional>
                  <ode/>
                </torsional>
                <ode/>
              </friction>
            </surface>
          </collision>
          <visual name='back_right_leg'>
            <pose frame=''>-0.68 -0.38 0.5 0 -0 0</pose>
            <geometry>
              <cylinder>
                <radius>0.02</radius>
                <length>1</length>
              </cylinder>
            </geometry>
            <material>
              <script>
                <uri>file://media/materials/scripts/gazebo.material</uri>
                <name>Gazebo/Grey</name>
              </script>
            </material>
          </visual>
          <collision name='back_left_leg'>
            <pose frame=''>-0.68 0.38 0.5 0 -0 0</pose>
            <geometry>
              <cylinder>
                <radius>0.02</radius>
                <length>1</length>
              </cylinder>
            </geometry>
            <max_contacts>10</max_contacts>
            <surface>
              <contact>
                <ode/>
              </contact>
              <bounce/>
              <friction>
                <torsional>
                  <ode/>
                </torsional>
                <ode/>
              </friction>
            </surface>
          </collision>
          <visual name='back_left_leg'>
            <pose frame=''>-0.68 0.38 0.5 0 -0 0</pose>
            <geometry>
              <cylinder>
                <radius>0.02</radius>
                <length>1</length>
              </cylinder>
            </geometry>
            <material>
              <script>
                <uri>file://media/materials/scripts/gazebo.material</uri>
                <name>Gazebo/Grey</name>
              </script>
            </material>
          </visual>
          <self_collide>0</self_collide>
          <kinematic>0</kinematic>
        </link>
        <pose frame=''>-1.76301 3.11808 -0.22703 0 -0 0</pose>
      </model>
      <model name='trisphere_cycle'>
        <link name='frame'>
          <pose frame=''>-0.408559 0 0.385023 0 -0.522021 0</pose>
          <inertial>
            <pose frame=''>0 0 0 0 -0 0</pose>
            <mass>10</mass>
            <inertia>
              <ixx>0.228</ixx>
              <iyy>0.743521</iyy>
              <izz>0.965521</izz>
              <ixy>0</ixy>
              <ixz>0</ixz>
              <iyz>0</iyz>
            </inertia>
          </inertial>
          <collision name='axle_collision'>
            <pose frame=''>-0.471335 0 0 1.5708 -0 0</pose>
            <geometry>
              <cylinder>
                <length>1.03923</length>
                <radius>0.03</radius>
              </cylinder>
            </geometry>
            <max_contacts>10</max_contacts>
            <surface>
              <contact>
                <ode/>
              </contact>
              <bounce/>
              <friction>
                <torsional>
                  <ode/>
                </torsional>
                <ode/>
              </friction>
            </surface>
          </collision>
          <visual name='axle_visual'>
            <pose frame=''>-0.471335 0 0 1.5708 -0 0</pose>
            <geometry>
              <cylinder>
                <length>1.03923</length>
                <radius>0.03</radius>
              </cylinder>
            </geometry>
            <material>
              <script>
                <uri>file://media/materials/scripts/gazebo.material</uri>
                <name>Gazebo/Grey</name>
              </script>
            </material>
          </visual>
          <collision name='frame_left_collision'>
            <pose frame=''>0 0.171552 0 -2.79253 1.57079 3.14159</pose>
            <geometry>
              <cylinder>
                <length>1.00317</length>
                <radius>0.03</radius>
              </cylinder>
            </geometry>
            <max_contacts>10</max_contacts>
            <surface>
              <contact>
                <ode/>
              </contact>
              <bounce/>
              <friction>
                <torsional>
                  <ode/>
                </torsional>
                <ode/>
              </friction>
            </surface>
          </collision>
          <visual name='frame_left_visual'>
            <pose frame=''>0 0.171552 0 -2.79253 1.57079 3.14159</pose>
            <geometry>
              <cylinder>
                <length>1.00317</length>
                <radius>0.03</radius>
              </cylinder>
            </geometry>
            <material>
              <script>
                <uri>file://media/materials/scripts/gazebo.material</uri>
                <name>Gazebo/Grey</name>
              </script>
            </material>
          </visual>
          <collision name='frame_right_collision'>
            <pose frame=''>0 -0.171552 0 2.79253 1.57079 -3.14159</pose>
            <geometry>
              <cylinder>
                <length>1.00317</length>
                <radius>0.03</radius>
              </cylinder>
            </geometry>
            <max_contacts>10</max_contacts>
            <surface>
              <contact>
                <ode/>
              </contact>
              <bounce/>
              <friction>
                <torsional>
                  <ode/>
                </torsional>
                <ode/>
              </friction>
            </surface>
          </collision>
          <visual name='frame_right_visual'>
            <pose frame=''>0 -0.171552 0 2.79253 1.57079 -3.14159</pose>
            <geometry>
              <cylinder>
                <length>1.00317</length>
                <radius>0.03</radius>
              </cylinder>
            </geometry>
            <material>
              <script>
                <uri>file://media/materials/scripts/gazebo.material</uri>
                <name>Gazebo/Grey</name>
              </script>
            </material>
          </visual>
          <self_collide>0</self_collide>
          <kinematic>0</kinematic>
        </link>
        <link name='fork'>
          <pose frame=''>0.041441 0 0.385023 0 -0.174533 0</pose>
          <inertial>
            <mass>3</mass>
            <inertia>
              <ixx>0.158203</ixx>
              <iyy>0.0583594</iyy>
              <izz>0.102656</izz>
              <ixy>0</ixy>
              <ixz>0</ixz>
              <iyz>0</iyz>
            </inertia>
          </inertial>
          <collision name='handlebars_collision'>
            <pose frame=''>0 0 0.397748 1.5708 -0 0</pose>
            <geometry>
              <cylinder>
                <length>0.636396</length>
                <radius>0.0375</radius>
              </cylinder>
            </geometry>
            <max_contacts>10</max_contacts>
            <surface>
              <contact>
                <ode/>
              </contact>
              <bounce/>
              <friction>
                <torsional>
                  <ode/>
                </torsional>
                <ode/>
              </friction>
            </surface>
          </collision>
          <visual name='handlebars_visual'>
            <pose frame=''>0 0 0.397748 1.5708 -0 0</pose>
            <geometry>
              <cylinder>
                <length>0.636396</length>
                <radius>0.0375</radius>
              </cylinder>
            </geometry>
            <material>
              <script>
                <uri>file://media/materials/scripts/gazebo.material</uri>
                <name>Gazebo/Grey</name>
              </script>
            </material>
          </visual>
          <collision name='headtube_collision'>
            <pose frame=''>0 0 0.238649 0 -0 0</pose>
            <geometry>
              <cylinder>
                <length>0.318198</length>
                <radius>0.0375</radius>
              </cylinder>
            </geometry>
            <max_contacts>10</max_contacts>
            <surface>
              <contact>
                <ode/>
              </contact>
              <bounce/>
              <friction>
                <torsional>
                  <ode/>
                </torsional>
                <ode/>
              </friction>
            </surface>
          </collision>
          <visual name='headtube_visual'>
            <pose frame=''>0 0 0.238649 0 -0 0</pose>
            <geometry>
              <cylinder>
                <length>0.318198</length>
                <radius>0.0375</radius>
              </cylinder>
            </geometry>
            <material>
              <script>
                <uri>file://media/materials/scripts/gazebo.material</uri>
                <name>Gazebo/Grey</name>
              </script>
            </material>
          </visual>
          <collision name='spindle_collision'>
            <pose frame=''>0 0 -0.238649 1.5708 -0 0</pose>
            <geometry>
              <cylinder>
                <length>0.636396</length>
                <radius>0.015</radius>
              </cylinder>
            </geometry>
            <max_contacts>10</max_contacts>
            <surface>
              <contact>
                <ode/>
              </contact>
              <bounce/>
              <friction>
                <torsional>
                  <ode/>
                </torsional>
                <ode/>
              </friction>
            </surface>
          </collision>
          <visual name='spindle_visual'>
            <pose frame=''>0 0 -0.238649 1.5708 -0 0</pose>
            <geometry>
              <cylinder>
                <length>0.636396</length>
                <radius>0.015</radius>
              </cylinder>
            </geometry>
            <material>
              <script>
                <uri>file://media/materials/scripts/gazebo.material</uri>
                <name>Gazebo/Grey</name>
              </script>
            </material>
          </visual>
          <collision name='fork_left_collision'>
            <pose frame=''>0 0.159099 -0.07955 0.785398 -0 0</pose>
            <geometry>
              <cylinder>
                <length>0.45</length>
                <radius>0.0375</radius>
              </cylinder>
            </geometry>
            <max_contacts>10</max_contacts>
            <surface>
              <contact>
                <ode/>
              </contact>
              <bounce/>
              <friction>
                <torsional>
                  <ode/>
                </torsional>
                <ode/>
              </friction>
            </surface>
          </collision>
          <visual name='fork_left_visual'>
            <pose frame=''>0 0.159099 -0.07955 0.785398 -0 0</pose>
            <geometry>
              <cylinder>
                <length>0.45</length>
                <radius>0.0375</radius>
              </cylinder>
            </geometry>
            <material>
              <script>
                <uri>file://media/materials/scripts/gazebo.material</uri>
                <name>Gazebo/Grey</name>
              </script>
            </material>
          </visual>
          <collision name='fork_right_collision'>
            <pose frame=''>0 -0.159099 -0.07955 -0.785398 0 0</pose>
            <geometry>
              <cylinder>
                <length>0.45</length>
                <radius>0.0375</radius>
              </cylinder>
            </geometry>
            <max_contacts>10</max_contacts>
            <surface>
              <contact>
                <ode/>
              </contact>
              <bounce/>
              <friction>
                <torsional>
                  <ode/>
                </torsional>
                <ode/>
              </friction>
            </surface>
          </collision>
          <visual name='fork_right_visual'>
            <pose frame=''>0 -0.159099 -0.07955 -0.785398 0 0</pose>
            <geometry>
              <cylinder>
                <length>0.45</length>
                <radius>0.0375</radius>
              </cylinder>
            </geometry>
            <material>
              <script>
                <uri>file://media/materials/scripts/gazebo.material</uri>
                <name>Gazebo/Grey</name>
              </script>
            </material>
          </visual>
          <self_collide>0</self_collide>
          <kinematic>0</kinematic>
        </link>
        <link name='wheel_front'>
          <pose frame=''>0.082882 0 0.15 0 -0 0</pose>
          <inertial>
            <mass>0.5</mass>
            <inertia>
              <ixx>0.0045</ixx>
              <iyy>0.0045</iyy>
              <izz>0.0045</izz>
              <ixy>0</ixy>
              <ixz>0</ixz>
              <iyz>0</iyz>
            </inertia>
          </inertial>
          <collision name='collision'>
            <geometry>
              <sphere>
                <radius>0.15</radius>
              </sphere>
            </geometry>
            <surface>
              <contact>
                <ode>
                  <kp>1e+08</kp>
                  <kd>1</kd>
                  <min_depth>0.0005</min_depth>
                </ode>
              </contact>
              <bounce/>
              <friction>
                <torsional>
                  <ode/>
                </torsional>
                <ode/>
              </friction>
            </surface>
            <max_contacts>10</max_contacts>
          </collision>
          <visual name='visual'>
            <geometry>
              <sphere>
                <radius>0.15</radius>
              </sphere>
            </geometry>
            <material>
              <script>
                <uri>file://media/materials/scripts/gazebo.material</uri>
                <name>Gazebo/Black</name>
              </script>
            </material>
          </visual>
          <self_collide>0</self_collide>
          <kinematic>0</kinematic>
        </link>
        <joint name='wheel_front_steer' type='revolute'>
          <parent>frame</parent>
          <child>fork</child>
          <axis>
            <xyz>0 0 1</xyz>
            <limit>
              <lower>-0.959931</lower>
              <upper>0.959931</upper>
            </limit>
            <use_parent_model_frame>0</use_parent_model_frame>
            <dynamics>
              <spring_reference>0</spring_reference>
              <spring_stiffness>0</spring_stiffness>
            </dynamics>
          </axis>
        </joint>
        <joint name='wheel_front_spin' type='revolute'>
          <parent>fork</parent>
          <child>wheel_front</child>
          <axis>
            <xyz>0 1 0</xyz>
            <use_parent_model_frame>0</use_parent_model_frame>
            <limit>
              <lower>-1e+16</lower>
              <upper>1e+16</upper>
            </limit>
            <dynamics>
              <spring_reference>0</spring_reference>
              <spring_stiffness>0</spring_stiffness>
            </dynamics>
          </axis>
        </joint>
        <link name='wheel_rear_left'>
          <pose frame=''>-0.817118 0.519615 0.15 0 -0 0</pose>
          <inertial>
            <mass>0.5</mass>
            <inertia>
              <ixx>0.0045</ixx>
              <iyy>0.0045</iyy>
              <izz>0.0045</izz>
              <ixy>0</ixy>
              <ixz>0</ixz>
              <iyz>0</iyz>
            </inertia>
          </inertial>
          <collision name='collision'>
            <geometry>
              <sphere>
                <radius>0.15</radius>
              </sphere>
            </geometry>
            <surface>
              <contact>
                <ode>
                  <kp>1e+08</kp>
                  <kd>1</kd>
                  <min_depth>0.0005</min_depth>
                </ode>
              </contact>
              <bounce/>
              <friction>
                <torsional>
                  <ode/>
                </torsional>
                <ode/>
              </friction>
            </surface>
            <max_contacts>10</max_contacts>
          </collision>
          <visual name='visual'>
            <geometry>
              <sphere>
                <radius>0.15</radius>
              </sphere>
            </geometry>
            <material>
              <script>
                <uri>file://media/materials/scripts/gazebo.material</uri>
                <name>Gazebo/Black</name>
              </script>
            </material>
          </visual>
          <self_collide>0</self_collide>
          <kinematic>0</kinematic>
        </link>
        <joint name='wheel_rear_left_spin' type='revolute'>
          <parent>frame</parent>
          <child>wheel_rear_left</child>
          <axis>
            <xyz>0 1 0</xyz>
            <use_parent_model_frame>0</use_parent_model_frame>
            <limit>
              <lower>-1e+16</lower>
              <upper>1e+16</upper>
            </limit>
            <dynamics>
              <spring_reference>0</spring_reference>
              <spring_stiffness>0</spring_stiffness>
            </dynamics>
          </axis>
        </joint>
        <link name='wheel_rear_right'>
          <pose frame=''>-0.817118 -0.519615 0.15 0 -0 0</pose>
          <inertial>
            <mass>0.5</mass>
            <inertia>
              <ixx>0.0045</ixx>
              <iyy>0.0045</iyy>
              <izz>0.0045</izz>
              <ixy>0</ixy>
              <ixz>0</ixz>
              <iyz>0</iyz>
            </inertia>
          </inertial>
          <collision name='collision'>
            <geometry>
              <sphere>
                <radius>0.15</radius>
              </sphere>
            </geometry>
            <surface>
              <contact>
                <ode>
                  <kp>1e+08</kp>
                  <kd>1</kd>
                  <min_depth>0.0005</min_depth>
                </ode>
              </contact>
              <bounce/>
              <friction>
                <torsional>
                  <ode/>
                </torsional>
                <ode/>
              </friction>
            </surface>
            <max_contacts>10</max_contacts>
          </collision>
          <visual name='visual'>
            <geometry>
              <sphere>
                <radius>0.15</radius>
              </sphere>
            </geometry>
            <material>
              <script>
                <uri>file://media/materials/scripts/gazebo.material</uri>
                <name>Gazebo/Black</name>
              </script>
            </material>
          </visual>
          <self_collide>0</self_collide>
          <kinematic>0</kinematic>
        </link>
        <joint name='wheel_rear_right_spin' type='revolute'>
          <parent>frame</parent>
          <child>wheel_rear_right</child>
          <axis>
            <xyz>0 1 0</xyz>
            <use_parent_model_frame>0</use_parent_model_frame>
            <limit>
              <lower>-1e+16</lower>
              <upper>1e+16</upper>
            </limit>
            <dynamics>
              <spring_reference>0</spring_reference>
              <spring_stiffness>0</spring_stiffness>
            </dynamics>
          </axis>
        </joint>
        <pose frame=''>4.0161 -5.88276 -0.22703 0 -0 0</pose>
      </model>
      <static>0</static>
      <allow_auto_disable>1</allow_auto_disable>
      <pose frame=''>1.01279 1.68991 0.22703 0 -0 0</pose>
    </model>
    <state world_name='default'>
      <sim_time>12 207000000</sim_time>
      <real_time>12 340369664</real_time>
      <wall_time>1565051745 368060570</wall_time>
      <iterations>12207</iterations>
      <model name='Untitled'>
        <pose frame=''>1.15444 0.530645 0 0 -0 0</pose>
        <scale>1 1 1</scale>
        <link name='Wall_3'>
          <pose frame=''>-4.14556 0.530645 0 0 0 -1.5708</pose>
          <velocity>0 0 0 0 -0 0</velocity>
          <acceleration>0 0 0 0 -0 0</acceleration>
          <wrench>0 0 0 0 -0 0</wrench>
        </link>
        <link name='Wall_4'>
          <pose frame=''>1.15444 -5.64436 0 0 -0 0</pose>
          <velocity>0 0 0 0 -0 0</velocity>
          <acceleration>0 0 0 0 -0 0</acceleration>
          <wrench>0 0 0 0 -0 0</wrench>
        </link>
        <link name='Wall_5'>
          <pose frame=''>6.45444 0.530645 0 0 -0 1.5708</pose>
          <velocity>0 0 0 0 -0 0</velocity>
          <acceleration>0 0 0 0 -0 0</acceleration>
          <wrench>0 0 0 0 -0 0</wrench>
        </link>
        <link name='Wall_6'>
          <pose frame=''>1.15444 6.70564 0 0 -0 3.14159</pose>
          <velocity>0 0 0 0 -0 0</velocity>
          <acceleration>0 0 0 0 -0 0</acceleration>
          <wrench>0 0 0 0 -0 0</wrench>
        </link>
      </model>
      <model name='Untitled_0'>
        <pose frame=''>1.01279 1.68991 0.22703 0 -0 0</pose>
        <scale>1 1 1</scale>
        <model name='Dumpster'>
          <pose frame=''>-2.0651 -4.05612 0 0 -0 0</pose>
          <scale>1 1 1</scale>
          <link name='link'>
            <pose frame=''>-2.0651 -4.05612 0 0 -0 0</pose>
            <velocity>0 0 0 0 -0 0</velocity>
            <acceleration>0 0 0 0 -0 0</acceleration>
            <wrench>0 0 0 0 -0 0</wrench>
          </link>
        </model>
        <model name='bowl'>
          <pose frame=''>-0.71334 4.84089 1.18218 0 -0 0</pose>
          <scale>1 1 1</scale>
          <link name='link'>
            <pose frame=''>-0.71334 4.84089 1.18218 0 -0 0</pose>
            <velocity>0 0 0 0 -0 0</velocity>
            <acceleration>0 0 0 0 -0 0</acceleration>
            <wrench>0 0 0 0 -0 0</wrench>
          </link>
        </model>
        <model name='cardboard_box'>
          <pose frame=''>0.112849 4.853 0.15 0 -0 0</pose>
          <scale>1 1 1</scale>
          <link name='link'>
            <pose frame=''>0.112849 4.853 0.15 0 -0 0</pose>
            <velocity>0 0 0 0 -0 0</velocity>
            <acceleration>0 0 0 0 -0 0</acceleration>
            <wrench>0 0 0 0 -0 0</wrench>
          </link>
        </model>
        <model name='prius_hybrid'>
          <pose frame=''>4.46366 3.88655 0.03 0 -0 0</pose>
          <scale>1 1 1</scale>
          <link name='chassis'>
            <pose frame=''>4.46366 3.88655 0.03 0 -0 0</pose>
            <velocity>0 0 0 0 -0 0</velocity>
            <acceleration>0 0 0 0 -0 0</acceleration>
            <wrench>0 0 0 0 -0 0</wrench>
          </link>
          <link name='front_left_wheel'>
            <pose frame=''>5.22366 2.47655 0.33 0 -0 0</pose>
            <velocity>0 0 0 0 -0 0</velocity>
            <acceleration>0 0 0 0 -0 0</acceleration>
            <wrench>0 0 0 0 -0 0</wrench>
          </link>
          <link name='front_right_wheel'>
            <pose frame=''>3.70366 2.47655 0.33 0 -0 0</pose>
            <velocity>0 0 0 0 -0 0</velocity>
            <acceleration>0 0 0 0 -0 0</acceleration>
            <wrench>0 0 0 0 -0 0</wrench>
          </link>
          <link name='rear_axle'>
            <pose frame=''>4.46366 5.33655 0.33 0 -0 0</pose>
            <velocity>0 0 0 0 -0 0</velocity>
            <acceleration>0 0 0 0 -0 0</acceleration>
            <wrench>0 0 0 0 -0 0</wrench>
          </link>
          <link name='rear_left_wheel'>
            <pose frame=''>5.24966 5.33655 0.33 0 -0 0</pose>
            <velocity>0 0 0 0 -0 0</velocity>
            <acceleration>0 0 0 0 -0 0</acceleration>
            <wrench>0 0 0 0 -0 0</wrench>
          </link>
          <link name='rear_right_wheel'>
            <pose frame=''>3.67766 5.33655 0.33 0 -0 0</pose>
            <velocity>0 0 0 0 -0 0</velocity>
            <acceleration>0 0 0 0 -0 0</acceleration>
            <wrench>0 0 0 0 -0 0</wrench>
          </link>
          <link name='steering_wheel'>
            <pose frame=''>4.82139 3.25868 1.01824 -1.3021 0 0</pose>
            <velocity>0 0 0 0 -0 0</velocity>
            <acceleration>0 0 0 0 -0 0</acceleration>
            <wrench>0 0 0 0 -0 0</wrench>
          </link>
        </model>
        <model name='table'>
          <pose frame=''>-0.75022 4.80799 0 0 -0 0</pose>
          <scale>1 1 1</scale>
          <link name='link'>
            <pose frame=''>-0.75022 4.80799 0 0 -0 0</pose>
            <velocity>0 0 0 0 -0 0</velocity>
            <acceleration>0 0 0 0 -0 0</acceleration>
            <wrench>0 0 0 0 -0 0</wrench>
          </link>
        </model>
        <model name='trisphere_cycle'>
          <pose frame=''>5.02889 -4.19285 0 0 -0 0</pose>
          <scale>1 1 1</scale>
          <link name='fork'>
            <pose frame=''>5.07033 -4.19285 0.385023 0 -0.174533 0</pose>
            <velocity>0 0 0 0 -0 0</velocity>
            <acceleration>0 0 0 0 -0 0</acceleration>
            <wrench>0 0 0 0 -0 0</wrench>
          </link>
          <link name='frame'>
            <pose frame=''>4.62033 -4.19285 0.385023 0 -0.522021 0</pose>
            <velocity>0 0 0 0 -0 0</velocity>
            <acceleration>0 0 0 0 -0 0</acceleration>
            <wrench>0 0 0 0 -0 0</wrench>
          </link>
          <link name='wheel_front'>
            <pose frame=''>5.11177 -4.19285 0.15 0 -0 0</pose>
            <velocity>0 0 0 0 -0 0</velocity>
            <acceleration>0 0 0 0 -0 0</acceleration>
            <wrench>0 0 0 0 -0 0</wrench>
          </link>
          <link name='wheel_rear_left'>
            <pose frame=''>4.21177 -3.67324 0.15 0 -0 0</pose>
            <velocity>0 0 0 0 -0 0</velocity>
            <acceleration>0 0 0 0 -0 0</acceleration>
            <wrench>0 0 0 0 -0 0</wrench>
          </link>
          <link name='wheel_rear_right'>
            <pose frame=''>4.21177 -4.71246 0.15 0 -0 0</pose>
            <velocity>0 0 0 0 -0 0</velocity>
            <acceleration>0 0 0 0 -0 0</acceleration>
            <wrench>0 0 0 0 -0 0</wrench>
          </link>
        </model>
      </model>
      <model name='ground_plane'>
        <pose frame=''>0 0 0 0 -0 0</pose>
        <scale>1 1 1</scale>
        <link name='link'>
          <pose frame=''>0 0 0 0 -0 0</pose>
          <velocity>0 0 0 0 -0 0</velocity>
          <acceleration>0 0 0 0 -0 0</acceleration>
          <wrench>0 0 0 0 -0 0</wrench>
        </link>
      </model>
      <light name='sun'>
        <pose frame=''>0 0 10 0 -0 0</pose>
      </light>
    </state>
    <gui fullscreen='0'>
      <camera name='user_camera'>
        <pose frame=''>4.56027 13.9339 15.2723 0 0.761797 -2.24301</pose>
        <view_controller>orbit</view_controller>
        <projection_type>perspective</projection_type>
      </camera>
    </gui>
  </world>
</sdf>
